2022-01-20 15:11:48,403 INFO    MainThread:396842 [internal.py:wandb_internal():87] W&B internal server running at pid: 396842, started at: 2022-01-20 15:11:48.402905
2022-01-20 15:11:48,404 DEBUG   HandlerThread:396842 [handler.py:handle_request():130] handle_request: check_version
2022-01-20 15:11:48,404 INFO    WriterThread:396842 [datastore.py:open_for_write():77] open: /home/minhhieu/Desktop/Hieu/SimpleHTR/src/wandb/run-20220120_151147-all_real_data_test/run-all_real_data_test.wandb
2022-01-20 15:11:48,405 DEBUG   SenderThread:396842 [sender.py:send():234] send: header
2022-01-20 15:11:48,405 DEBUG   SenderThread:396842 [sender.py:send_request():248] send_request: check_version
2022-01-20 15:11:48,578 DEBUG   SenderThread:396842 [sender.py:send():234] send: run
2022-01-20 15:11:49,085 ERROR   SenderThread:396842 [internal_api.py:execute():144] 409 response executing GraphQL.
2022-01-20 15:11:49,086 ERROR   SenderThread:396842 [internal_api.py:execute():145] {"errors":[{"message":"Error 1062: Duplicate entry '659751-all_real_data_test' for key 'PRIMARY'","path":["upsertBucket"]}],"data":{"upsertBucket":null}}
2022-01-20 15:11:49,579 INFO    HandlerThread:396842 [handler.py:finish():731] shutting down handler
2022-01-20 15:11:49,583 INFO    WriterThread:396842 [datastore.py:close():281] close: /home/minhhieu/Desktop/Hieu/SimpleHTR/src/wandb/run-20220120_151147-all_real_data_test/run-all_real_data_test.wandb
2022-01-20 15:11:49,583 ERROR   MainThread:396842 [internal.py:wandb_internal():158] Thread SenderThread:
Traceback (most recent call last):
  File "/home/minhhieu/.local/lib/python3.8/site-packages/wandb/apis/normalize.py", line 24, in wrapper
    return func(*args, **kwargs)
  File "/home/minhhieu/.local/lib/python3.8/site-packages/wandb/sdk/internal/internal_api.py", line 1298, in upsert_run
    response = self.gql(mutation, variable_values=variable_values, **kwargs)
  File "/home/minhhieu/.local/lib/python3.8/site-packages/wandb/sdk/lib/retry.py", line 102, in __call__
    result = self._call_fn(*args, **kwargs)
  File "/home/minhhieu/.local/lib/python3.8/site-packages/wandb/sdk/internal/internal_api.py", line 147, in execute
    six.reraise(*sys.exc_info())
  File "/home/minhhieu/.local/lib/python3.8/site-packages/six.py", line 703, in reraise
    raise value
  File "/home/minhhieu/.local/lib/python3.8/site-packages/wandb/sdk/internal/internal_api.py", line 141, in execute
    return self.client.execute(*args, **kwargs)
  File "/home/minhhieu/.local/lib/python3.8/site-packages/wandb/vendor/gql-0.2.0/gql/client.py", line 52, in execute
    result = self._get_result(document, *args, **kwargs)
  File "/home/minhhieu/.local/lib/python3.8/site-packages/wandb/vendor/gql-0.2.0/gql/client.py", line 60, in _get_result
    return self.transport.execute(document, *args, **kwargs)
  File "/home/minhhieu/.local/lib/python3.8/site-packages/wandb/vendor/gql-0.2.0/gql/transport/requests.py", line 39, in execute
    request.raise_for_status()
  File "/usr/lib/python3/dist-packages/requests/models.py", line 940, in raise_for_status
    raise HTTPError(http_error_msg, response=self)
requests.exceptions.HTTPError: 409 Client Error: Conflict for url: https://api.wandb.ai/graphql

During handling of the above exception, another exception occurred:

Traceback (most recent call last):
  File "/home/minhhieu/.local/lib/python3.8/site-packages/wandb/sdk/internal/internal_util.py", line 52, in run
    self._run()
  File "/home/minhhieu/.local/lib/python3.8/site-packages/wandb/sdk/internal/internal_util.py", line 102, in _run
    self._process(record)
  File "/home/minhhieu/.local/lib/python3.8/site-packages/wandb/sdk/internal/internal.py", line 291, in _process
    self._sm.send(record)
  File "/home/minhhieu/.local/lib/python3.8/site-packages/wandb/sdk/internal/sender.py", line 236, in send
    send_handler(record)
  File "/home/minhhieu/.local/lib/python3.8/site-packages/wandb/sdk/internal/sender.py", line 687, in send_run
    self._init_run(run, config_value_dict)
  File "/home/minhhieu/.local/lib/python3.8/site-packages/wandb/sdk/internal/sender.py", line 711, in _init_run
    server_run, inserted = self._api.upsert_run(
  File "/home/minhhieu/.local/lib/python3.8/site-packages/wandb/apis/normalize.py", line 26, in wrapper
    raise CommError(err.response, err)
wandb.errors.CommError: <Response [409]>
2022-01-20 15:11:51,659 INFO    MainThread:396842 [internal.py:handle_exit():77] Internal process exited
